Workbook

Sheet DACS19 - Pfizer’s Personali (2)
A1: Patient_ID | B1: Age | C1: Gender | D1: Ethnicity | E1: Medical_History | F1: Genomic_Profile | G1: Trial_ID | H1: Drug_Name | I1: Trial_Phase | J1: Start_Date | K1: End_Date | L1: Dose | M1: Adverse_Events | N1: Treatment_ID | O1: Dose_Administered | P1: Treatment_Outcome | Q1: Side_Effects | R1: Duration_of_Treatment | S1: Success_Indicator | T1: Gene_Name | U1: Mutation_Status | V1: Expression_Level | W1: Biomarker_Level | X1: Efficacy_Score | Y1: Survival_Rate | Z1: Progression_Free_Survival
A2: P001 | B2: 22 | C2: Male | D2: African American | E2: Heart Disease | F2: None | G2: T011 | H2: DrugC | I2: Phase IV | J2: 9/16/2023 | K2: 5/16/2024 | L2: 200mg | M2: Fatigue, Nausea | N2: TR0085 | O2: 200mg | P2: Improved | Q2: Headache | R2: 95 | S2: 1 | T2: BRCA2 | U2: Positive | V2: 3.79 | W2: 3.14 | X2: 3.8 | Y2: 20.6 | Z2: 14.6
A3: P002 | B3: 61 | C3: Female | D3: Other | E3: Diabetes | F3: HER2 Mutation | G3: T014 | H3: DrugC | I3: Phase I | J3: 11/4/2022 | K3: 7/4/2023 | L3: 100mg | M3: None, Fatigue | N3: TR0002 | O3: 100mg | P3: No Change | Q3: Headache | R3: 90 | S3: 0 | T3: HER2 | U3: Negative | V3: 1.65 | W3: 4.64 | X3: 8.4 | Y3: 23.1 | Z3: 15.3
A4: P003 | B4: 60 | C4: Female | D4: Other | E4: Heart Disease | F4: TP53 Mutation | G4: T008 | H4: DrugA | I4: Phase I | J4: 5/6/2022 | K4: 5/6/2023 | L4: 150mg | M4: Nausea, None, Fatigue | N4: TR0158 | O4: 150mg | P4: Improved | Q4: Fatigue | R4: 64 | S4: 1 | T4: HER2 | U4: Positive | V4: 3.45 | W4: 2.67 | X4: 9.4 | Y4: 21.6 | Z4: 3.8
A5: P004 | B5: 76 | C5: Other | D5: Other | E5: None | F5: EGFR Mutation | G5: T016 | H5: DrugB | I5: Phase II | J5: 2/17/2023 | K5: 3/17/2024 | L5: 150mg | M5: Dizziness | N5: TR0029 | O5: 150mg | P5: Improved | Q5: Dizziness | R5: 159 | S5: 1 | T5: BRCA2 | U5: Positive | V5: 1.11 | W5: 2.51 | X5: 8.3 | Y5: 23.8 | Z5: 5.6
A6: P005 | B6: 39 | C6: Female | D6: Other | E6: Asthma | F6: BRCA2 Mutation | G6: T019 | H6: DrugD | I6: Phase I | J6: 8/26/2023 | K6: 2/26/2024 | L6: 200mg | M6: Dizziness | N6: TR0107 | O6: 200mg | P6: No Change | Q6: Dizziness | R6: 44 | S6: 0 | T6: EGFR | U6: Negative | V6: 3.38 | W6: 2.52 | X6: 9.7 | Y6: 21.2 | Z6: 17.3
A7: P006 | B7: 57 | C7: Other | D7: Caucasian | E7: Asthma | F7: BRCA1 Mutation | G7: T007 | H7: DrugA | I7: Phase I | J7: 6/23/2022 | K7: 1/23/2023 | L7: 50mg | M7: Headache | N7: TR0009 | O7: 50mg | P7: No Change | Q7: Headache | R7: 76 | S7: 0 | T7: BRCA2 | U7: Negative | V7: 2.87 | W7: 2.66 | X7: 3.5 | Y7: 7 | Z7: 17.7
A8: P007 | B8: 65 | C8: Female | D8: Hispanic | E8: Asthma | F8: EGFR Mutation | G8: T005 | H8: DrugC | I8: Phase I | J8: 9/13/2020 | K8: 11/13/2021 | L8: 100mg | M8: Fatigue, Nausea, Headache | N8: TR0077 | O8: 100mg | P8: No Change | Q8: Dizziness | R8: 138 | S8: 0 | T8: EGFR | U8: Negative | V8: 4.25 | W8: 5 | X8: 10 | Y8: 16 | Z8: 16.1
A9: P008 | B9: 47 | C9: Male | D9: Hispanic | E9: None | F9: BRCA2 Mutation | G9: T004 | H9: DrugA | I9: Phase IV | J9: 1/8/2023 | K9: 10/8/2023 | L9: 50mg | M9: Dizziness | N9: TR0009 | O9: 50mg | P9: No Change | Q9: Dizziness | R9: 42 | S9: 0 | T9: BRCA2 | U9: Positive | V9: 4.78 | W9: 4.4 | X9: 3.2 | Y9: 14.1 | Z9: 5.2
A10: P009 | B10: 69 | C10: Female | D10: Asian | E10: Heart Disease | F10: BRCA1 Mutation | G10: T005 | H10: DrugC | I10: Phase II | J10: 6/19/2023 | K10: 9/19/2024 | L10: 150mg | M10: None | N10: TR0037 | O10: 150mg | P10: Deteriorated | Q10: Dizziness | R10: 86 | S10: 0 | T10: HER2 | U10: Negative | V10: 4.82 | W10: 3.42 | X10: 3.1 | Y10: 18.1 | Z10: 13.5
A11: P010 | B11: 53 | C11: Male | D11: Other | E11: Heart Disease | F11: None | G11: T006 | H11: DrugD | I11: Phase IV | J11: 6/21/2019 | K11: 10/21/2020 | L11: 200mg | M11: None, Headache, Fatigue | N11: TR0039 | O11: 200mg | P11: No Change | Q11: Headache | R11: 77 | S11: 0 | T11: EGFR | U11: Negative | V11: 2.43 | W11: 1.45 | X11: 7 | Y11: 15.4 | Z11: 16.1
A12: P011 | B12: 48 | C12: Male | D12: African American | E12: Diabetes | F12: None | G12: T002 | H12: DrugD | I12: Phase IV | J12: 9/5/2023 | K12: 9/5/2024 | L12: 100mg | M12: Fatigue, None | N12: TR0166 | O12: 100mg | P12: Improved | Q12: Headache | R12: 124 | S12: 1 | T12: BRCA1 | U12: Positive | V12: 3.08 | W12: 4.41 | X12: 6 | Y12: 16.1 | Z12: 17.9
A13: P012 | B13: 24 | C13: Female | D13: Hispanic | E13: Heart Disease | F13: None | G13: T003 | H13: DrugB | I13: Phase II | J13: 4/28/2022 | K13: 3/28/2023 | L13: 150mg | M13: Fatigue | N13: TR0049 | O13: 150mg | P13: Deteriorated | Q13: Nausea | R13: 152 | S13: 0 | T13: BRCA2 | U13: Positive | V13: 2.61 | W13: 1.54 | X13: 1.3 | Y13: 19.6 | Z13: 13.5
... A1001: P1000 | B1001: 70 | C1001: Other | D1001: Caucasian | E1001: None | F1001: None | G1001: T017 | H1001: DrugD | I1001: Phase II | J1001: 1/23/2020 | K1001: 12/23/2020 | L1001: 150mg | M1001: None | N1001: TR0002 | O1001: 150mg | P1001: No Change | Q1001: Nausea | R1001: 164 | S1001: 0 | T1001: EGFR | U1001: Positive | V1001: 2.34 | W1001: 3.32 | X1001: 9 | Y1001: 16.2 | Z1001: 13.7

Sheet Pivot_Analysis
A3: Age Group | B3: Count of Patient_ID | G3: Drug | H3: Improvement Rate
A4: 18-30 | B4: 197 | G4: DrugA | H4: =76/244 -> 0.31147541
A5: 31-50 | B5: 286 | G5: DrugB | H5: =80/235 -> 0.34042553
A6: 51-65 | B6: 229 | G6: DrugC | H6: =104/270 -> 0.38518519
A7: 66+ | B7: 288 | G7: DrugD | H7: =87/251 -> 0.34661355
A8: Grand Total | B8: 1000
A12: Count of Patient_ID | B12: Column Labels
A13: Drug | B13: Phase I | C13: Phase II | D13: Phase III | E13: Phase IV | F13: Grand Total
A14: DrugA | B14: 64 | C14: 63 | D14: 55 | E14: 62 | F14: 244
A15: DrugB | B15: 58 | C15: 55 | D15: 67 | E15: 55 | F15: 235
A16: DrugC | B16: 69 | C16: 68 | D16: 69 | E16: 64 | F16: 270
A17: DrugD | B17: 66 | C17: 62 | D17: 64 | E17: 59 | F17: 251
A18: Grand Total | B18: 257 | C18: 248 | D18: 255 | E18: 240 | F18: 1000
A22: Count of Patient_ID | B22: Column Labels
A23: Drug | B23: Deteriorated | C23: Improved | D23: No Change | E23: Grand Total
A24: DrugA | B24: 85 | C24: 76 | D24: 83 | E24: 244
A25: DrugB | B25: 76 | C25: 80 | D25: 79 | E25: 235
A26: DrugC | B26: 79 | C26: 104 | D26: 87 | E26: 270
A27: DrugD | B27: 71 | C27: 87 | D27: 93 | E27: 251
A28: Grand Total | B28: 311 | C28: 347 | D28: 342 | E28: 1000
A32: Count of Patient_ID | B32: Column Labels
A33: Side Effects | B33: DrugA | C33: DrugB | D33: DrugC | E33: DrugD | F33: Grand Total
A34: Dizziness | B34: 52 | C34: 38 | D34: 57 | E34: 62 | F34: 209
A35: Fatigue | B35: 55 | C35: 51 | D35: 48 | E35: 51 | F35: 205
A36: Headache | B36: 45 | C36: 45 | D36: 60 | E36: 56 | F36: 206
A37: Nausea | B37: 57 | C37: 56 | D37: 58 | E37: 42 | F37: 213
A38: Not Reported | B38: 35 | C38: 45 | D38: 47 | E38: 40 | F38: 167
A39: Grand Total | B39: 244 | C39: 235 | D39: 270 | E39: 251 | F39: 1000
A42: Drug | B42: Dizziness Rate | C42: Fatigue | D42: Headache | E42: Nausea
A43: DrugA | B43: =52/244 -> 0.21311475 | C43: =55/244 -> 0.22540984 | D43: =45/244 -> 0.18442623 | E43: =57/244 -> 0.23360656
A44: DrugB | B44: =38/235 -> 0.16170213 | C44: =51/235 -> 0.21702128 | D44: =45/235 -> 0.19148936 | E44: =56/235 -> 0.23829787
A45: DrugC | B45: =57/270 -> 0.21111111 | C45: =48/270 -> 0.17777778 | D45: =60/270 -> 0.22222222 | E45: =58/270 -> 0.21481481
A46: DrugD | B46: =62/251 -> 0.24701195 | C46: =51/251 -> 0.20318725 | D46: =56/251 -> 0.22310757 | E46: =42/251 -> 0.16733068
A50: Count of Patient_ID | B50: Column Labels
A51: Dose | B51: Deteriorated | C51: Improved | D51: No Change | E51: Grand Total | G51: Dose | H51: Improvement Rate
A52: 50 | B52: 82 | C52: 85 | D52: 78 | E52: 245 | G52: 50mg | H52: =85/245 -> 0.34693878
A53: 100 | B53: 78 | C53: 89 | D53: 95 | E53: 262 | G53: 100mg | H53: =89/262 -> 0.33969466
A54: 150 | B54: 78 | C54: 76 | D54: 85 | E54: 239 | G54: 150mg | H54: =76/239 -> 0.31799163
A55: 200 | B55: 73 | C55: 97 | D55: 84 | E55: 254 | G55: 200mg | H55: =97/254 -> 0.38188976
A56: Grand Total | B56: 311 | C56: 347 | D56: 342 | E56: 1000
...

Sheet Clean_Data
A1: Patient_ID | B1: Age | C1: Gender | D1: Ethnicity | E1: Medical_History | F1: Genomic_Profile | G1: Trial_ID | H1: Drug_Name | I1: Trial_Phase | J1: Start_Date | K1: End_Date | L1: Dose | M1: Adverse_Events | N1: Treatment_ID | O1: Dose_Administered | P1: Treatment_Outcome | Q1: Side_Effects | R1: Duration_of_Treatment | S1: Success_Indicator | T1: Gene_Name | U1: Mutation_Status | V1: Expression_Level | W1: Biomarker_Level | X1: Efficacy_Score | Y1: Survival_Rate | Z1: Progression_Free_Survival | AA1: Dose_Numeric | AB1: Dose_Administered_Numeric | AC1: Side_Effects2 | AD1: Side_Effects_Numeric | AE1: Treatment_Outcome_Numeric | AF1: Drug_A_Biomarker | AG1: Drug_B_Biomarker | AH1: Drug_C_Biomarker | AI1: Drug_D_Biomarker
A2: P001 | B2: 22 | C2: Male | D2: African American | E2: Heart Disease | F2: Not Reported | G2: T011 | H2: DrugC | I2: Phase IV | J2: 9/16/2023 | K2: 5/16/2024 | L2: 200mg | M2: Fatigue, Nausea | N2: TR0085 | O2: 200mg | P2: Improved | Q2: Headache | R2: 95 | S2: 1 | T2: BRCA2 | U2: Positive | V2: 3.79 | W2: 3.14 | X2: 3.8 | Y2: 20.6 | Z2: 14.6 | AA2: =VALUE(SUBSTITUTE(DACS19___Pfizer’s_Personalised_Medicine_in[[#This Row],[Dose]],"mg","")) -> 200 | AB2: =VALUE(SUBSTITUTE(O2,"mg","")) -> 200 | AC2: Headache | AD2: =IF(Q2="","",IF(Q2="Dizziness",1,IF(Q2="Fatigue",2,IF(Q2="Headache",3,IF(Q2="Nausea",4,IF(Q2="Not Reported",0,"")))))) -> 3 | AE2: =IF(P2="Deteriorated",1,IF(P2="No Change",2,IF(P2="Improved",3,0))) -> 3 | AF2: =IF($H2="DrugA",$W2,NA()) -> #N/A | AG2: =IF($H2="DrugB",$W2,NA()) -> #N/A | AH2: =IF($H2="DrugC",$W2,NA()) -> 3.14 | AI2: =IF($H2="DrugD",$W2,NA()) -> #N/A
A3: P002 | B3: 61 | C3: Female | D3: Other | E3: Diabetes | F3: HER2 Mutation | G3: T014 | H3: DrugC | I3: Phase I | J3: 11/4/2022 | K3: 7/4/2023 | L3: 100mg | M3: Not Reported, Fatigue | N3: TR0002 | O3: 100mg | P3: No Change | Q3: Headache | R3: 90 | S3: 0 | T3: HER2 | U3: Negative | V3: 1.65 | W3: 4.64 | X3: 8.4 | Y3: 23.1 | Z3: 15.3 | AA3: =VALUE(SUBSTITUTE(DACS19___Pfizer’s_Personalised_Medicine_in[[#This Row],[Dose]],"mg","")) -> 100 | AB3: =VALUE(SUBSTITUTE(O3,"mg","")) -> 100 | AC3: Headache | AD3: =IF(Q3="","",IF(Q3="Dizziness",1,IF(Q3="Fatigue",2,IF(Q3="Headache",3,IF(Q3="Nausea",4,IF(Q3="Not Reported",0,"")))))) -> 3 | AE3: =IF(P3="Deteriorated",1,IF(P3="No Change",2,IF(P3="Improved",3,0))) -> 2 | AF3: =IF($H3="DrugA",$W3,NA()) -> #N/A | AG3: =IF($H3="DrugB",$W3,NA()) -> #N/A | AH3: =IF($H3="DrugC",$W3,NA()) -> 4.64 | AI3: =IF($H3="DrugD",$W3,NA()) -> #N/A
A4: P003 | B4: 60 | C4: Female | D4: Other | E4: Heart Disease | F4: TP53 Mutation | G4: T008 | H4: DrugA | I4: Phase I | J4: 5/6/2022 | K4: 5/6/2023 | L4: 150mg | M4: Nausea, Not Reported, Fatigue | N4: TR0158 | O4: 150mg | P4: Improved | Q4: Fatigue | R4: 64 | S4: 1 | T4: HER2 | U4: Positive | V4: 3.45 | W4: 2.67 | X4: 9.4 | Y4: 21.6 | Z4: 3.8 | AA4: =VALUE(SUBSTITUTE(DACS19___Pfizer’s_Personalised_Medicine_in[[#This Row],[Dose]],"mg","")) -> 150 | AB4: =VALUE(SUBSTITUTE(O4,"mg","")) -> 150 | AC4: Fatigue | AD4: =IF(Q4="","",IF(Q4="Dizziness",1,IF(Q4="Fatigue",2,IF(Q4="Headache",3,IF(Q4="Nausea",4,IF(Q4="Not Reported",0,"")))))) -> 2 | AE4: =IF(P4="Deteriorated",1,IF(P4="No Change",2,IF(P4="Improved",3,0))) -> 3 | AF4: =IF($H4="DrugA",$W4,NA()) -> 2.67 | AG4: =IF($H4="DrugB",$W4,NA()) -> #N/A | AH4: =IF($H4="DrugC",$W4,NA()) -> #N/A | AI4: =IF($H4="DrugD",$W4,NA()) -> #N/A
A5: P004 | B5: 76 | C5: Other | D5: Other | E5: Not Reported | F5: EGFR Mutation | G5: T016 | H5: DrugB | I5: Phase II | J5: 2/17/2023 | K5: 3/17/2024 | L5: 150mg | M5: Dizziness | N5: TR0029 | O5: 150mg | P5: Improved | Q5: Dizziness | R5: 159 | S5: 1 | T5: BRCA2 | U5: Positive | V5: 1.11 | W5: 2.51 | X5: 8.3 | Y5: 23.8 | Z5: 5.6 | AA5: =VALUE(SUBSTITUTE(DACS19___Pfizer’s_Personalised_Medicine_in[[#This Row],[Dose]],"mg","")) -> 150 | AB5: =VALUE(SUBSTITUTE(O5,"mg","")) -> 150 | AC5: Dizziness | AD5: =IF(Q5="","",IF(Q5="Dizziness",1,IF(Q5="Fatigue",2,IF(Q5="Headache",3,IF(Q5="Nausea",4,IF(Q5="Not Reported",0,"")))))) -> 1 | AE5: =IF(P5="Deteriorated",1,IF(P5="No Change",2,IF(P5="Improved",3,0))) -> 3 | AF5: =IF($H5="DrugA",$W5,NA()) -> #N/A | AG5: =IF($H5="DrugB",$W5,NA()) -> 2.51 | AH5: =IF($H5="DrugC",$W5,NA()) -> #N/A | AI5: =IF($H5="DrugD",$W5,NA()) -> #N/A
A6: P005 | B6: 39 | C6: Female | D6: Other | E6: Asthma | F6: BRCA2 Mutation | G6: T019 | H6: DrugD | I6: Phase I | J6: 8/26/2023 | K6: 2/26/2024 | L6: 200mg | M6: Dizziness | N6: TR0107 | O6: 200mg | P6: No Change | Q6: Dizziness | R6: 44 | S6: 0 | T6: EGFR | U6: Negative | V6: 3.38 | W6: 2.52 | X6: 9.7 | Y6: 21.2 | Z6: 17.3 | AA6: =VALUE(SUBSTITUTE(DACS19___Pfizer’s_Personalised_Medicine_in[[#This Row],[Dose]],"mg","")) -> 200 | AB6: =VALUE(SUBSTITUTE(O6,"mg","")) -> 200 | AC6: Dizziness | AD6: =IF(Q6="","",IF(Q6="Dizziness",1,IF(Q6="Fatigue",2,IF(Q6="Headache",3,IF(Q6="Nausea",4,IF(Q6="Not Reported",0,"")))))) -> 1 | AE6: =IF(P6="Deteriorated",1,IF(P6="No Change",2,IF(P6="Improved",3,0))) -> 2 | AF6: =IF($H6="DrugA",$W6,NA()) -> #N/A | AG6: =IF($H6="DrugB",$W6,NA()) -> #N/A | AH6: =IF($H6="DrugC",$W6,NA()) -> #N/A | AI6: =IF($H6="DrugD",$W6,NA()) -> 2.52
A7: P006 | B7: 57 | C7: Other | D7: Caucasian | E7: Asthma | F7: BRCA1 Mutation | G7: T007 | H7: DrugA | I7: Phase I | J7: 6/23/2022 | K7: 1/23/2023 | L7: 50mg | M7: Headache | N7: TR0009 | O7: 50mg | P7: No Change | Q7: Headache | R7: 76 | S7: 0 | T7: BRCA2 | U7: Negative | V7: 2.87 | W7: 2.66 | X7: 3.5 | Y7: 7 | Z7: 17.7 | AA7: =VALUE(SUBSTITUTE(DACS19___Pfizer’s_Personalised_Medicine_in[[#This Row],[Dose]],"mg","")) -> 50 | AB7: =VALUE(SUBSTITUTE(O7,"mg","")) -> 50 | AC7: Headache | AD7: =IF(Q7="","",IF(Q7="Dizziness",1,IF(Q7="Fatigue",2,IF(Q7="Headache",3,IF(Q7="Nausea",4,IF(Q7="Not Reported",0,"")))))) -> 3 | AE7: =IF(P7="Deteriorated",1,IF(P7="No Change",2,IF(P7="Improved",3,0))) -> 2 | AF7: =IF($H7="DrugA",$W7,NA()) -> 2.66 | AG7: =IF($H7="DrugB",$W7,NA()) -> #N/A | AH7: =IF($H7="DrugC",$W7,NA()) -> #N/A | AI7: =IF($H7="DrugD",$W7,NA()) -> #N/A
A8: P007 | B8: 65 | C8: Female | D8: Hispanic | E8: Asthma | F8: EGFR Mutation | G8: T005 | H8: DrugC | I8: Phase I | J8: 9/13/2020 | K8: 11/13/2021 | L8: 100mg | M8: Fatigue, Nausea, Headache | N8: TR0077 | O8: 100mg | P8: No Change | Q8: Dizziness | R8: 138 | S8: 0 | T8: EGFR | U8: Negative | V8: 4.25 | W8: 5 | X8: 10 | Y8: 16 | Z8: 16.1 | AA8: =VALUE(SUBSTITUTE(DACS19___Pfizer’s_Personalised_Medicine_in[[#This Row],[Dose]],"mg","")) -> 100 | AB8: =VALUE(SUBSTITUTE(O8,"mg","")) -> 100 | AC8: Dizziness | AD8: =IF(Q8="","",IF(Q8="Dizziness",1,IF(Q8="Fatigue",2,IF(Q8="Headache",3,IF(Q8="Nausea",4,IF(Q8="Not Reported",0,"")))))) -> 1 | AE8: =IF(P8="Deteriorated",1,IF(P8="No Change",2,IF(P8="Improved",3,0))) -> 2 | AF8: =IF($H8="DrugA",$W8,NA()) -> #N/A | AG8: =IF($H8="DrugB",$W8,NA()) -> #N/A | AH8: =IF($H8="DrugC",$W8,NA()) -> 5 | AI8: =IF($H8="DrugD",$W8,NA()) -> #N/A
A9: P008 | B9: 47 | C9: Male | D9: Hispanic | E9: Not Reported | F9: BRCA2 Mutation | G9: T004 | H9: DrugA | I9: Phase IV | J9: 1/8/2023 | K9: 10/8/2023 | L9: 50mg | M9: Dizziness | N9: TR0009 | O9: 50mg | P9: No Change | Q9: Dizziness | R9: 42 | S9: 0 | T9: BRCA2 | U9: Positive | V9: 4.78 | W9: 4.4 | X9: 3.2 | Y9: 14.1 | Z9: 5.2 | AA9: =VALUE(SUBSTITUTE(DACS19___Pfizer’s_Personalised_Medicine_in[[#This Row],[Dose]],"mg","")) -> 50 | AB9: =VALUE(SUBSTITUTE(O9,"mg","")) -> 50 | AC9: Dizziness | AD9: =IF(Q9="","",IF(Q9="Dizziness",1,IF(Q9="Fatigue",2,IF(Q9="Headache",3,IF(Q9="Nausea",4,IF(Q9="Not Reported",0,"")))))) -> 1 | AE9: =IF(P9="Deteriorated",1,IF(P9="No Change",2,IF(P9="Improved",3,0))) -> 2 | AF9: =IF($H9="DrugA",$W9,NA()) -> 4.4 | AG9: =IF($H9="DrugB",$W9,NA()) -> #N/A | AH9: =IF($H9="DrugC",$W9,NA()) -> #N/A | AI9: =IF($H9="DrugD",$W9,NA()) -> #N/A
A10: P009 | B10: 69 | C10: Female | D10: Asian | E10: Heart Disease | F10: BRCA1 Mutation | G10: T005 | H10: DrugC | I10: Phase II | J10: 6/19/2023 | K10: 9/19/2024 | L10: 150mg | M10: Not Reported | N10: TR0037 | O10: 150mg | P10: Deteriorated | Q10: Dizziness | R10: 86 | S10: 0 | T10: HER2 | U10: Negative | V10: 4.82 | W10: 3.42 | X10: 3.1 | Y10: 18.1 | Z10: 13.5 | AA10: =VALUE(SUBSTITUTE(DACS19___Pfizer’s_Personalised_Medicine_in[[#This Row],[Dose]],"mg","")) -> 150 | AB10: =VALUE(SUBSTITUTE(O10,"mg","")) -> 150 | AC10: Dizziness | AD10: =IF(Q10="","",IF(Q10="Dizziness",1,IF(Q10="Fatigue",2,IF(Q10="Headache",3,IF(Q10="Nausea",4,IF(Q10="Not Reported",0,"")))))) -> 1 | AE10: =IF(P10="Deteriorated",1,IF(P10="No Change",2,IF(P10="Improved",3,0))) -> 1 | AF10: =IF($H10="DrugA",$W10,NA()) -> #N/A | AG10: =IF($H10="DrugB",$W10,NA()) -> #N/A | AH10: =IF($H10="DrugC",$W10,NA()) -> 3.42 | AI10: =IF($H10="DrugD",$W10,NA()) -> #N/A
A11: P010 | B11: 53 | C11: Male | D11: Other | E11: Heart Disease | F11: Not Reported | G11: T006 | H11: DrugD | I11: Phase IV | J11: 6/21/2019 | K11: 10/21/2020 | L11: 200mg | M11: Not Reported, Headache, Fatigue | N11: TR0039 | O11: 200mg | P11: No Change | Q11: Headache | R11: 77 | S11: 0 | T11: EGFR | U11: Negative | V11: 2.43 | W11: 1.45 | X11: 7 | Y11: 15.4 | Z11: 16.1 | AA11: =VALUE(SUBSTITUTE(DACS19___Pfizer’s_Personalised_Medicine_in[[#This Row],[Dose]],"mg","")) -> 200 | AB11: =VALUE(SUBSTITUTE(O11,"mg","")) -> 200 | AC11: Headache | AD11: =IF(Q11="","",IF(Q11="Dizziness",1,IF(Q11="Fatigue",2,IF(Q11="Headache",3,IF(Q11="Nausea",4,IF(Q11="Not Reported",0,"")))))) -> 3 | AE11: =IF(P11="Deteriorated",1,IF(P11="No Change",2,IF(P11="Improved",3,0))) -> 2 | AF11: =IF($H11="DrugA",$W11,NA()) -> #N/A | AG11: =IF($H11="DrugB",$W11,NA()) -> #N/A | AH11: =IF($H11="DrugC",$W11,NA()) -> #N/A | AI11: =IF($H11="DrugD",$W11,NA()) -> 1.45
A12: P011 | B12: 48 | C12: Male | D12: African American | E12: Diabetes | F12: Not Reported | G12: T002 | H12: DrugD | I12: Phase IV | J12: 9/5/2023 | K12: 9/5/2024 | L12: 100mg | M12: Fatigue, Not Reported | N12: TR0166 | O12: 100mg | P12: Improved | Q12: Headache | R12: 124 | S12: 1 | T12: BRCA1 | U12: Positive | V12: 3.08 | W12: 4.41 | X12: 6 | Y12: 16.1 | Z12: 17.9 | AA12: =VALUE(SUBSTITUTE(DACS19___Pfizer’s_Personalised_Medicine_in[[#This Row],[Dose]],"mg","")) -> 100 | AB12: =VALUE(SUBSTITUTE(O12,"mg","")) -> 100 | AC12: Headache | AD12: =IF(Q12="","",IF(Q12="Dizziness",1,IF(Q12="Fatigue",2,IF(Q12="Headache",3,IF(Q12="Nausea",4,IF(Q12="Not Reported",0,"")))))) -> 3 | AE12: =IF(P12="Deteriorated",1,IF(P12="No Change",2,IF(P12="Improved",3,0))) -> 3 | AF12: =IF($H12="DrugA",$W12,NA()) -> #N/A | AG12: =IF($H12="DrugB",$W12,NA()) -> #N/A | AH12: =IF($H12="DrugC",$W12,NA()) -> #N/A | AI12: =IF($H12="DrugD",$W12,NA()) -> 4.41
A13: P012 | B13: 24 | C13: Female | D13: Hispanic | E13: Heart Disease | F13: Not Reported | G13: T003 | H13: DrugB | I13: Phase II | J13: 4/28/2022 | K13: 3/28/2023 | L13: 150mg | M13: Fatigue | N13: TR0049 | O13: 150mg | P13: Deteriorated | Q13: Nausea | R13: 152 | S13: 0 | T13: BRCA2 | U13: Positive | V13: 2.61 | W13: 1.54 | X13: 1.3 | Y13: 19.6 | Z13: 13.5 | AA13: =VALUE(SUBSTITUTE(DACS19___Pfizer’s_Personalised_Medicine_in[[#This Row],[Dose]],"mg","")) -> 150 | AB13: =VALUE(SUBSTITUTE(O13,"mg","")) -> 150 | AC13: Nausea | AD13: =IF(Q13="","",IF(Q13="Dizziness",1,IF(Q13="Fatigue",2,IF(Q13="Headache",3,IF(Q13="Nausea",4,IF(Q13="Not Reported",0,"")))))) -> 4 | AE13: =IF(P13="Deteriorated",1,IF(P13="No Change",2,IF(P13="Improved",3,0))) -> 1 | AF13: =IF($H13="DrugA",$W13,NA()) -> #N/A | AG13: =IF($H13="DrugB",$W13,NA()) -> 1.54 | AH13: =IF($H13="DrugC",$W13,NA()) -> #N/A | AI13: =IF($H13="DrugD",$W13,NA()) -> #N/A
... A1001: P1000 | B1001: 70 | C1001: Other | D1001: Caucasian | E1001: Not Reported | F1001: Not Reported | G1001: T017 | H1001: DrugD | I1001: Phase II | J1001: 1/23/2020 | K1001: 12/23/2020 | L1001: 150mg | M1001: Not Reported | N1001: TR0002 | O1001: 150mg | P1001: No Change | Q1001: Nausea | R1001: 164 | S1001: 0 | T1001: EGFR | U1001: Positive | V1001: 2.34 | W1001: 3.32 | X1001: 9 | Y1001: 16.2 | Z1001: 13.7 | AA1001: =VALUE(SUBSTITUTE(DACS19___Pfizer’s_Personalised_Medicine_in[[#This Row],[Dose]],"mg","")) -> 150 | AB1001: =VALUE(SUBSTITUTE(O1001,"mg","")) -> 150 | AC1001: Nausea | AD1001: =IF(Q1001="","",IF(Q1001="Dizziness",1,IF(Q1001="Fatigue",2,IF(Q1001="Headache",3,IF(Q1001="Nausea",4,IF(Q1001="Not Reported",0,"")))))) -> 4 | AE1001: =IF(P1001="Deteriorated",1,IF(P1001="No Change",2,IF(P1001="Improved",3,0))) -> 2 | AF1001: =IF($H1001="DrugA",$W1001,NA()) -> #N/A | AG1001: =IF($H1001="DrugB",$W1001,NA()) -> #N/A | AH1001: =IF($H1001="DrugC",$W1001,NA()) -> #N/A | AI1001: =IF($H1001="DrugD",$W1001,NA()) -> 3.32

Sheet Charts

Sheet Data_Quality
A1: A | B1: B | C1: C
A2: Column | B2: Missing Count | C2: Missing %
A3: Patient_ID | B3: =COUNTBLANK(Clean_Data!A2:A1001) -> 0 | C3: =B3/1000 -> 0
A4: Age | B4: =COUNTIF(Clean_Data!B2:B1001,"None") -> 0 | C4: =B4/1000 -> 0
A5: Gender | B5: =COUNTIF(Clean_Data!C2:C1001,"None") -> 0 | C5: =B5/1000 -> 0
A6: Ethnicity | B6: =COUNTIF(Clean_Data!D2:D1001,"None") -> 0 | C6: =B6/1000 -> 0
A7: Medical_History | B7: =COUNTIF(Clean_Data!E2:E1001,"None") -> 0 | C7: =B7/1000 -> 0
A8: Genomic_Profile | B8: =COUNTIF(Clean_Data!F2:F1001,"None") -> 0 | C8: =B8/1000 -> 0
A9: Adverse_Events | B9: =COUNTIF(Clean_Data!M2:M1001,"None") -> 0 | C9: =B9/1000 -> 0
A10: Side_Effects | B10: =COUNTIF(Clean_Data!Q2:Q1001,"None") -> 0 | C10: =B10/1000 -> 0
A11: Survival_Rate | B11: =COUNTIF(Clean_Data!Y2:Y1001,"None") -> 0 | C11: =B11/1000 -> 0
A13: Check | B13: Result
A14: Total Records | B14: =COUNTA(Clean_Data!A2:A1001) -> 1000
A15: Unique Patient IDs | B15: {=SUMPRODUCT(1/COUNTIF(Clean_Data!A2:A1001, Clean_Data!A2:A1001))} -> 1000
A16: Duplicate Patient IDs | B16: =B14-B15 -> 0
A18: Check | B18: Minimum | C18: Maximum
A19: Age | B19: =MIN(Clean_Data!B2:B1001) -> 18 | C19: =MAX(Clean_Data!B2:B1001) -> 85
A20: Duration of Treatment | B20: =MIN(Clean_Data!R2:R1001) -> 30 | C20: =MAX(Clean_Data!R2:R1001) -> 180
A21: Efficacy Score | B21: =MIN(Clean_Data!X2:X1001) -> 1 | C21: =MAX(Clean_Data!X2:X1001) -> 10
A22: Survival Rate | B22: =MIN(Clean_Data!Y2:Y1001) -> 6 | C22: =MAX(Clean_Data!Y2:Y1001) -> 24
A23: Progression Free Survival | B23: =MIN(Clean_Data!Z2:Z1001) -> 3 | C23: =MAX(Clean_Data!Z2:Z1001) -> 20
